Workbook

Sheet Raw Data
A2: Data Cleaning
A5: 2025-01-05 | Laptop | Electronics | North | 185000 | 2 | H5: Follow these Steps;
A6: 2025-01-12 | Office Chair | Furniture | South | 18500 | 5
A7: 2025-01-18 | Men's Jacket | Clothing | East | 7500 | 8
A8: 2025-01-25 | LED TV 42" | Electronics | West | 95000 | 3 | H8: Remove Duplicates
H9: Text to Columns
A10: 2025-02-03 | Refrigerator | Electronics | North | 125000 | 1 | H10: Trim
A11: 2025-02-10 | Study Table | Furniture | South | 22000 | 4 | H11: Clean
A12: 2025-02-14 | Women's Handbag | Clothing | East | 6500 | 6 | H12: PROPER/UPPER/LOWER
A13: 2025-02-20 | Printer | Electronics | West | 32000 | 2 | H13: Sorting
H14: Filtering
A15: 2025-03-02 | Microwave Oven | Electronics | North | 28000 | 3 | H15: Find & Replace
A16: 2025-03-09 | Sofa Set | Furniture | South | 145000 | 1 | H16: Remove Blanks
A17: 2025-03-15 | Sneakers | Clothing | East | 9500 | 7
A18: 2025-03-22 | Cooking Oil 5L | Groceries | West | 2800 | 10
A20: 2025-04-04 | Smartphone | Electronics | North | 115000 | 4
A21: 2025-04-12 | Wardrobe | Furniture | South | 85000 | 2
A22: 2025-04-18 | Rice 10kg | Groceries | East | 3200 | 12
A23: 2025-04-26 | Office Desk | Furniture | West | 35000 | 3
A25: 2025-05-03 | Air Conditioner | Electronics | North | 165000 | 2
A26: 2025-05-11 | T-Shirts Pack | Clothing | South | 4500 | 10
A27: 2025-05-19 | Washing Machine | Electronics | East | 98000 | 1
A28: 2025-05-28 | School Bag | Stationery | West | 3500 | 9
A30: 2025-06-06 | Tablet | Electronics | North | 65000 | 3
A31: 2025-06-14 | Bed Frame | Furniture | South | 72000 | 2
... A63: 2025-12-28 | Eraser Pack | Stationery | West | 400 | 40

Sheet Cleaned Data
A1: Date | B1: Product | C1: Category | D1: Region | E1: Price (PKR) | F1: Quantity | H1: Date | I1: Product | J1: Category | K1: Region | L1: Price | M1: QTY
A2: 45662 | B2: Laptop | C2: Electronics | D2: North | E2: 185000 | F2: 2 | H2: 45662 | I2: =VLOOKUP($H$2,$A$1:$F$51,COLUMN()-7,0) -> Laptop | J2: =VLOOKUP($H$2,$A$1:$F$51,COLUMN()-7,0) -> Electronics | K2: =VLOOKUP($H$2,$A$1:$F$51,COLUMN()-7,0) -> North | L2: =VLOOKUP($H$2,$A$1:$F$51,COLUMN()-7,0) -> 185000 | M2: =VLOOKUP($H$2,$A$1:$F$51,COLUMN()-7,0) -> 2
A3: 45669 | B3: Office Chair | C3: Furniture | D3: South | E3: 18500 | F3: 4
A4: 45677 | B4: Men's Jacket | C4: Clothing | D4: East | E4: 6500 | F4: 6
A5: 45690 | B5: LED TV 42" | C5: Electronics | D5: West | E5: 98000 | F5: 3
A6: 45702 | B6: Dining Table | C6: Furniture | D6: North | E6: 75000 | F6: 1
A7: 45713 | B7: Rice 10kg | C7: Groceries | D7: South | E7: 4200 | F7: 8
A8: 45719 | B8: Smartphone | C8: Electronics | D8: East | E8: 72000 | F8: 5
A9: 45731 | B9: Bed Set | C9: Furniture | D9: West | E9: 135000 | F9: 1
A10: 45738 | B10: Women's Handbag | C10: Clothing | D10: North | E10: 4500 | F10: 7
A11: 45748 | B11: Air Conditioner | C11: Electronics | D11: South | E11: 165000 | F11: 2
A12: 45757 | B12: Study Desk | C12: Furniture | D12: East | E12: 22000 | F12: 3
A13: 45765 | B13: Flour 20kg | C13: Groceries | D13: West | E13: 3100 | F13: 10
A14: 45782 | B14: Headphones | C14: Electronics | D14: North | E14: 8500 | F14: 6
... A51: 45921 | B51: Bed Sheet Set | C51: Furniture | D51: South | E51: 7500 | F51: 6

Sheet Data Table
A1: Date | B1: Product | C1: Category | D1: Region | E1: Price (PKR) | F1: Quantity
A2: 45662 | B2: Laptop | C2: Electronics | D2: North | E2: 185000 | F2: 2
A3: 45669 | B3: Office Chair | C3: Furniture | D3: South | E3: 18500 | F3: 4
A4: 45677 | B4: Men's Jacket | C4: Clothing | D4: East | E4: 6500 | F4: 6
A5: 45690 | B5: LED TV 42" | C5: Electronics | D5: West | E5: 98000 | F5: 3
A6: 45702 | B6: Dining Table | C6: Furniture | D6: North | E6: 75000 | F6: 1
A7: 45713 | B7: Rice 10kg | C7: Groceries | D7: South | E7: 4200 | F7: 8
A8: 45719 | B8: Smartphone | C8: Electronics | D8: East | E8: 72000 | F8: 5
A9: 45731 | B9: Bed Set | C9: Furniture | D9: West | E9: 135000 | F9: 1
A10: 45738 | B10: Women's Handbag | C10: Clothing | D10: North | E10: 4500 | F10: 7
A11: 45748 | B11: Air Conditioner | C11: Electronics | D11: South | E11: 165000 | F11: 2
A12: 45757 | B12: Study Desk | C12: Furniture | D12: East | E12: 22000 | F12: 3
A13: 45765 | B13: Flour 20kg | C13: Groceries | D13: West | E13: 3100 | F13: 10
... A51: 45921 | B51: Bed Sheet Set | C51: Furniture | D51: South | E51: 7500 | F51: 6

Sheet Pivot Table
A2: 📊 PIVOT TABLE FEATURES
A6: Sum of Price (PKR) | B6: Column Labels
A7: Row Labels | B7: Clothing | C7: Electronics | D7: Furniture | E7: Groceries | F7: Grand Total
A8: Abaya | B8: 6000 | F8: 6000
A9: Air Conditioner | C9: 165000 | F9: 165000
A10: Bed Set | D10: 135000 | F10: 135000
A11: Bed Sheet Set | D11: 7500 | F11: 7500
A12: Bluetooth Speaker | C12: 13500 | F12: 13500
A13: Bookshelf | D13: 15000 | F13: 15000
A14: Bottled Water Pack | E14: 1200 | F14: 1200
A15: Camera | C15: 165000 | F15: 165000
A16: Coffee Table | D16: 16500 | F16: 16500
A17: Computer Table | D17: 27000 | F17: 27000
A18: Cooking Oil 5L | E18: 2800 | F18: 2800
A19: Curtains Set | D19: 12500 | F19: 12500
A20: Dining Table | D20: 75000 | F20: 75000
A21: Dressing Table | D21: 28500 | F21: 28500
A22: Eggs (Dozen) | E22: 420 | F22: 420
A23: Flour 20kg | E23: 3100 | F23: 3100
A24: Gaming Console | C24: 125000 | F24: 125000
A25: Headphones | C25: 8500 | F25: 8500
A26: Hoodie | B26: 3200 | F26: 3200
A27: Jacket | B27: 8500 | F27: 8500
A28: Jeans | B28: 4000 | F28: 4000
A29: Kids T-Shirt | B29: 1200 | F29: 1200
A30: Laptop | C30: 185000 | F30: 185000
A31: LED TV 42" | C31: 98000 | F31: 98000
A32: Lentils 2kg | E32: 680 | F32: 680
A33: Mattress | D33: 24000 | F33: 24000
A34: Men's Jacket | B34: 6500 | F34: 6500
A35: Men's Shoes | B35: 7500 | F35: 7500
A36: Microwave Oven | C36: 36500 | F36: 36500
A37: Milk 1L | E37: 220 | F37: 220
A38: Office Chair | D38: 18500 | F38: 18500
A39: Office Table | D39: 34000 | F39: 34000
A40: Power Bank | C40: 4500 | F40: 4500
A41: Printer | C41: 45000 | F41: 45000
A42: Refrigerator | C42: 155000 | F42: 155000
A43: Rice 10kg | E43: 4200 | F43: 4200
A44: Shoe Rack | D44: 9500 | F44: 9500
...

Sheet LOOKUP Functions
A2: 🔎 LOOKUP FUNCTIONS
A5: VLOOKUP | F5: OFFSET | L5: INDEX
A6: VLOOKUP(lookup_value, table_array, col_index, FALSE) | F6: OFFSET(reference, rows, cols) | L6: INDEX(array, row_num, [column_num])
A7: =IFERROR(VLOOKUP('Cleaned Data'!B38,'Cleaned Data'!B2:F51,4,FALSE),"0") -> 45000 | F7: =OFFSET('Cleaned Data'!B5,6,2) -> South | L7: =INDEX(Table1[#All],4,3) -> Clothing | S7: Elaris | T7: Jennie
S8: Paul | T8: Kather
A9: XLOOKUP(Version!) | F9: INDIRECT | L9: MATCH | S9: 22 | T9: 23
A10: XLOOKUP(lookup_value, lookup_array, return_array) | F10: INDIRECT(ref_text) | L10: MATCH(lookup_value, lookup_array, 0)
F11: =INDIRECT("S7") -> Elaris | L11: =MATCH('Data Table'!B8, Table1[[#All],[Product]],0) -> 8
A13: HLOOKUP | F13: CHOOSE | L13: LOOKUP
A14: HLOOKUP(value, table, row_index, FALSE) | F14: CHOOSE(index_num, value1, value2, ...) | L14: LOOKUP(lookup_value, lookup_vector, result_vector)
A15: =HLOOKUP("Laptop",'Cleaned Data'!B2:F51, 1,FALSE) -> Laptop | F15: =CHOOSE(2, "North", "South", "East") -> South | L15: =LOOKUP(T7,T7:T9,S7:S9) -> Elaris
A17: INDEX + MATCH | F17: TRANSPOSE
A18: INDEX(return_range, MATCH(value, lookup_range, 0)) | F18: TRANSPOSE(array) ---CTRL+SHIFT+ENTER (MUST)
A19: =INDEX('Cleaned Data'!E2:E51, MATCH('Cleaned Data'!B35,'Cleaned Data'!B2:B51,0)) -> 22000 | F19: {=TRANSPOSE('Cleaned Data'!B2:D4)} -> Laptop | G19: {=TRANSPOSE('Cleaned Data'!C2:E4)} -> Electronics | H19: {=TRANSPOSE('Cleaned Data'!D2:F4)} -> North | I19: {=TRANSPOSE('Cleaned Data'!E2:G4)} -> 185000
F20: {=TRANSPOSE('Cleaned Data'!B3:D5)} -> Office Chair | G20: {=TRANSPOSE('Cleaned Data'!C3:E5)} -> Furniture | H20: {=TRANSPOSE('Cleaned Data'!D3:F5)} -> South | I20: {=TRANSPOSE('Cleaned Data'!E3:G5)} -> 18500
F21: {=TRANSPOSE('Cleaned Data'!B4:D6)} -> Men's Jacket | G21: {=TRANSPOSE('Cleaned Data'!C4:E6)} -> Clothing | H21: {=TRANSPOSE('Cleaned Data'!D4:F6)} -> East | I21: {=TRANSPOSE('Cleaned Data'!E4:G6)} -> 6500
F22: {=TRANSPOSE('Cleaned Data'!B5:D7)} -> LED TV 42" | G22: {=TRANSPOSE('Cleaned Data'!C5:E7)} -> Electronics | H22: {=TRANSPOSE('Cleaned Data'!D5:F7)} -> West | I22: {=TRANSPOSE('Cleaned Data'!E5:G7)} -> 98000
F23: {=TRANSPOSE('Cleaned Data'!B6:D8)} -> Dining Table | G23: {=TRANSPOSE('Cleaned Data'!C6:E8)} -> Furniture | H23: {=TRANSPOSE('Cleaned Data'!D6:F8)} -> North | I23: {=TRANSPOSE('Cleaned Data'!E6:G8)} -> 75000

Sheet Logical Functions
A2: 🧠 LOGICAL FUNCTIONS
S5: ID | T5: Name | U5: Age | V5: Gender | W5: City | X5: Score | Y5: Status
A6: IF | G6: SUMIF | M6: COUNTIF | S6: 1 | T6: Aisha | U6: 22 | V6: Female | W6: Karachi | X6: 85 | Y6: Pass
A7: IF(condition, value_if_true, value_if_false) | G7: SUMIF(range, criteria, sum_range) | M7: COUNTIF(range, criteria) | S7: 2 | T7: Rahul | U7: 24 | V7: Male | W7: Lahore | X7: 78 | Y7: Pass
A8: =IF('Cleaned Data'!E2>10000, "In Budget", "Expensive") -> In Budget | G8: =SUMIF('Cleaned Data'!C2:C50,"Electronics",'Cleaned Data'!E2:E51) -> 1340000 | M8: =COUNTIF('Cleaned Data'!D2:D50,"North") -> 13 | S8: 3 | T8: Fatima | U8: 21 | V8: Female | W8: Islamabad | X8: 92 | Y8: Pass
S9: 4 | T9: Ahmed | U9: 23 | V9: Male | W9: Peshawar | X9: 67 | Y9: Pass
A10: IFS(not valid) | G10: SUMIFS | M10: COUNTIFS(range1,crit1,range2,crit2) | S10: 5 | T10: Zoya | U10: 25 | V10: Female | W10: Quetta | X10: 74 | Y10: Pass
A11: IFS(cond1,val1, cond2,val2) | G11: SUMIFS(sum_range, criteria_range1, criteria1, ...) | M11: COUNTIFS(range1,crit1,range2,crit2) | S11: 6 | T11: Ali | U11: 22 | V11: Male | W11: Multan | X11: 58 | Y11: Fail
G12: 450000 | M12: =COUNTIFS('Cleaned Data'!D2:D50,"North",'Cleaned Data'!C2:C50,"Electronics") -> 7 | S12: 7 | T12: Sana | U12: 23 | V12: Female | W12: Faisalabad | X12: 81 | Y12: Pass
S13: 8 | T13: Bilal | U13: 26 | V13: Male | W13: Hyderabad | X13: 49 | Y13: Fail
A14: AND | G14: NOT | M14: IF/OR | S14: 9 | T14: Mehak | U14: 24 | V14: Female | W14: Sialkot | X14: 88 | Y14: Pass
A15: AND(condition1, condition2, ...) | G15: NOT(condition) | M15: IF(OR(condition1, condition2), value_if_true, value_if_false) | S15: 10 | T15: Usman | U15: 27 | V15: Male | W15: Gujranwala | X15: 73 | Y15: Pass
A16: =AND(X6>60, U7<30) -> TRUE | G16: =NOT(X6>60) -> FALSE | M16: =IF(OR(X6>60, U6>30), "Priority", "Normal") -> Priority
A18: OR | G18: IF/AND | M18: IF/AND/OR
A19: OR(condition1, condition2, ...) | G19: IF(AND(condition1, condition2), value_if_true, value_if_false) | M19: IF(AND(condition1, OR(condition2, condition3)), value_if_true, value_if_false)
A20: =OR(X6>60, U6>30) -> TRUE | G20: =IF(AND(X6>60, U7<30), "Target Achieved", "Not Achieved") -> Target Achieved | M20: =IF(AND(X6>20, OR(W6 ="Karachi", W9="Sialkot")), "Priority", "Normal") -> Priority

Sheet Text Functions
X1: A
A2: 🔤 TEXT FUNCTIONS | X2: B
X3: C
W4: Microsoft Excel | X4: D
A5: LEFT | G5: FIND | M5: PROPER | S5: TEXT | W5: Microsoft Excel | X5: E
A6: LEFT(text, num_characters) | G6: FIND(find_text, within_text, [start_position]) | M6: PROPER(text) | S6: TEXT(value, format_text) | W6: Microsoft Excel
A7: =LEFT(W4,4) -> Micr | G7: =FIND("c",W4) -> 3 | M7: =PROPER(W7) -> Microsoft Excel | S7: =TEXT(TODAY(),"dd-mmm-yyyy") -> 10-Feb-2026 | W7: mICrOSoft ExcEL
A9: RIGHT | G9: SEARCH | M9: UPPER | S9: VALUE
A10: LEFT(text, num_characters) | G10: SEARCH(find_text, within_text, [start_position]) | M10: UPPER(text) | S10: VALUE(text)
A11: =RIGHT(W4,4) -> xcel | G11: =SEARCH("E",W4) -> 11 | M11: =UPPER(W7) -> MICROSOFT EXCEL | S11: =VALUE("125000") -> 125000
A13: MID | G13: TRIM | M13: LOWER | S13: REPLACE
A14: MID(text, start_position, num_characters) | G14: TRIM(text) | M14: LOWER(text) | S14: REPLACE(old_text, start_num, num_chars, new_text)
A15: =MID(W4,6,4) -> soft | G15: =TRIM(W5) -> Microsoft Excel | M15: =LOWER(W7) -> microsoft excel | S15: =REPLACE("Laptop","1",3,"Phone") -> Phonetop
A17: LEN | G17: CLEAN | M17: CONCAT | S17: EXACT
A18: LEN(text) | G18: CLEAN(text) | M18: CONCAT(text1, text2, ...) | S18: EXACT(text1, text2)
A19: =LEN(W4) -> 15 | G19: =CLEAN(W6) -> Microsoft Excel | M19: =CONCATENATE(X1,X2,X3,X4,X5) -> ABCDE | S19: =EXACT("Laptop","laptop") -> FALSE
A21: TEXTAFTER | G21: TEXTSPLIT
A22: TEXTAFTER(text, delimiter) | G22: TEXTSPLIT(text, col_delimiter)
A23: not valid | G23: not valid

Sheet Error Functions
A2: 🚨 ERROR FUNCTIONS
A5: ISERROR | G5: ISNA | R5: Product | S5: Quantity
A6: ISERROR(value) | G6: ISNA(value) | R6: Laptop | S6: 2
A7: =ISERROR(A2/B2) -> TRUE | G7: =ISNA(VLOOKUP("Tablet", R5:S10, 2, FALSE)) -> TRUE | R7: Chair | S7: 0
R8: T-Shirt | S8: 8
A9: ISBLANK | G9: IFNA | R9: LED TV | S9: 3
A10: ISBLANK(value) | G10: IFNA(value, value_if_na) | R10: Notebook | S10: 10
A11: =ISBLANK(C2) -> TRUE | G11: =_xlfn.IFNA(VLOOKUP("Tablet", R5:S10, 2, FALSE), "Not Found") -> Not Found
A13: IFERROR | G13: ISTEXT
A14: IFERROR(value, value_if_error) | G14: ISTEXT(value)
A15: =IFERROR(S6/S7," Error " ) -> Error | G15: =ISTEXT(R6) -> TRUE
A17: ISNUMBER | G17: ERROR.TYPE
A18: ISNUMBER(value) | G18: ERROR.TYPE(error_val)
A19: =ISNUMBER(S6/S7) -> FALSE | G19: =ERROR.TYPE(S6/S7) -> 2

Sheet Date Functions
N1: WEEKDAY
A2: 📅 DATE FUNCTIONS | N2: WEEKDAY(date, [return_type])
N3: =WEEKDAY("09/02/2026",2) -> 1
A5: TODAY | G5: DATEDIF | N5: WORKDAY
A6: TODAY() | G6: DATEDIF(start_date, end_date, "unit") | N6: WORKDAY(start_date, days, [holidays])
A7: =TODAY() -> 46063 | G7: =DATEDIF("01/01/2020","09/02/2026","y") -> 6 | N7: =WORKDAY("10/02/2026",5) -> 46070
A9: NOW | G9: DAY | N9: NETWORKDAYS
A10: NOW() | G10: DAY(date) | N10: NETWORKDAYS(start_date, end_date, [holidays])
A11: =NOW() -> 46063.877 | G11: =DAY("09/02/2026") -> 9 | N11: =NETWORKDAYS("01/02/2026","10/02/2026") -> 7
A13: DATE | G13: MONTH | N13: EDATE
A14: DATE(year, month, day) | G14: MONTH(date) | N14: EDATE(start_date, months)
A15: =DATE(2003,8,6) -> 37839 | G15: =MONTH("09/02/2026") -> 2 | N15: =EDATE("09/02/2026", 3) -> 46151
A17: EOMONTH | G17: YEAR | N17: DATEVALUE
A18: EOMONTH(start_date, months) | G18: YEAR(date) | N18: DATEVALUE("text_date")
A19: =EOMONTH("09/02/2026",-1) -> 46053 | G19: =YEAR("09/02/2026") -> 2026 | N19: =DATEVALUE("9-Feb-2026") -> 46062

Sheet Statis+Analy Functions (1)
A2: 📊 Statistical & Analysis Functions
A5: SUMPRODUCT | G5: RANK | M5: ROUND | S5: MOD
A9: SUBTOTAL | G9: PERCENTILE | M9: CEILING | S9: ROUNDUP
A13: AGGREGATE | G13: AVERAGE | M13: FLOOR
A17: LARGE | G17: MIN/MAX | M17: ABS

Sheet Statis+Analy Functions (2)
A2: 📊 Statistical & Analysis Functions
A5: FORECAST | G5: MEDIAN | M5: STDEV.P
A9: ROUNDDOWN | G9: MEAN | M9: STDEV.S
A13: SMALL | G13: MODE.SNGL | M13: VAR.P
A17: FREQUENCY | G17: CORREL | M17: VAR.S

Sheet Financial & Accounts Functions
A2: 💰 Financial & Accounts Functions
A5: PMT | G5: IRR | M5: XNPV | S5: SLN
A9: PV | G9: RATE | M9: XIRR | S9: DOLLAR
A13: FV | G13: DB | M13: CUMIPMT | S13: FIXED
A17: NPV | G17: NPER | M17: CUMPRINC
